{
  "version": 8,
  "blockIdVersion": 11,
  "anchorX": 0,
  "anchorY": 0,
  "anchorZ": 0,
  "blocks": [
    {
      "x": -1,
      "y": 0,
      "z": -1,
      "name": "Soil_Grass"
    },
    {
      "x": -1,
      "y": 1,
      "z": -1,
      "name": "Plant_Fruit_Apple"
    },
    {
      "x": -1,
      "y": 2,
      "z": -1,
      "name": "Empty"
    },
    {
      "x": -1,
      "y": 0,
      "z": 0,
      "name": "Soil_Dirt"
    },
    {
      "x": -1,
      "y": 1,
      "z": 0,
      "name": "Empty"
    },
    {
      "x": -1,
      "y": 2,
      "z": 0,
      "name": "Empty"
    },
    {
      "x": -1,
      "y": 0,
      "z": 1,
      "name": "Soil_Grass"
    },
    {
      "x": -1,
      "y": 1,
      "z": 1,
      "name": "Plant_Bush",
      "support": 15
    },
    {
      "x": -1,
      "y": 2,
      "z": 1,
      "name": "Empty"
    },
    {
      "x": 0,
      "y": 0,
      "z": -1,
      "name": "Soil_Grass"
    },
    {
      "x": 0,
      "y": 1,
      "z": -1,
      "name": "Empty"
    },
    {
      "x": 0,
      "y": 2,
      "z": -1,
      "name": "Empty"
    },
    {
      "x": 0,
      "y": 0,
      "z": 0,
      "name": "Stone_Offering_Tray"
    },
    {
      "x": 0,
      "y": 1,
      "z": 0,
      "name": "Empty"
    },
    {
      "x": 0,
      "y": 2,
      "z": 0,
      "name": "Empty"
    },
    {
      "x": 0,
      "y": 0,
      "z": 1,
      "name": "Soil_Grass"
    },
    {
      "x": 0,
      "y": 1,
      "z": 1,
      "name": "Wayside_Shrine",
      "rotation": 2
    },
    {
      "x": 0,
      "y": 2,
      "z": 1,
      "name": "Wayside_Shrine",
      "filler": 1024,
      "rotation": 2
    },
    {
      "x": 1,
      "y": 0,
      "z": -1,
      "name": "Soil_Grass"
    },
    {
      "x": 1,
      "y": 1,
      "z": -1,
      "name": "Empty"
    },
    {
      "x": 1,
      "y": 2,
      "z": -1,
      "name": "Empty"
    },
    {
      "x": 1,
      "y": 0,
      "z": 0,
      "name": "Soil_Dirt"
    },
    {
      "x": 1,
      "y": 1,
      "z": 0,
      "name": "Empty"
    },
    {
      "x": 1,
      "y": 2,
      "z": 0,
      "name": "Empty"
    },
    {
      "x": 1,
      "y": 0,
      "z": 1,
      "name": "Soil_Grass"
    },
    {
      "x": 1,
      "y": 1,
      "z": 1,
      "name": "Plant_Crop_Mushroom_Cap_Red",
      "components": {
        "Components": {
          "FarmingBlock": {
            "LastTickGameTime": "0001-01-01T12:00:00Z"
          },
          "PlacedByInteraction": {
            "WhoPlacedUuid": {
              "$binary": "7RgS5j+2Q7iGDrSXx3YJoA==",
              "$type": "04"
            }
          }
        }
      }
    },
    {
      "x": 1,
      "y": 2,
      "z": 1,
      "name": "Empty"
    },
    {
      "x": -1,
      "y": -1,
      "z": -1,
      "name": "Soil_Dirt"
    },
    {
      "x": -1,
      "y": -2,
      "z": -1,
      "name": "Soil_Dirt"
    },
    {
      "x": -1,
      "y": -1,
      "z": 0,
      "name": "Soil_Dirt"
    },
    {
      "x": -1,
      "y": -2,
      "z": 0,
      "name": "Soil_Dirt"
    },
    {
      "x": -1,
      "y": -1,
      "z": 1,
      "name": "Soil_Dirt"
    },
    {
      "x": -1,
      "y": -2,
      "z": 1,
      "name": "Soil_Dirt"
    },
    {
      "x": 0,
      "y": -1,
      "z": -1,
      "name": "Soil_Dirt"
    },
    {
      "x": 0,
      "y": -2,
      "z": -1,
      "name": "Soil_Dirt"
    },
    {
      "x": 0,
      "y": -1,
      "z": 0,
      "name": "Soil_Dirt"
    },
    {
      "x": 0,
      "y": -2,
      "z": 0,
      "name": "Soil_Dirt"
    },
    {
      "x": 0,
      "y": -1,
      "z": 1,
      "name": "Soil_Dirt"
    },
    {
      "x": 0,
      "y": -2,
      "z": 1,
      "name": "Soil_Dirt"
    },
    {
      "x": 1,
      "y": -1,
      "z": -1,
      "name": "Soil_Dirt"
    },
    {
      "x": 1,
      "y": -2,
      "z": -1,
      "name": "Soil_Dirt"
    },
    {
      "x": 1,
      "y": -1,
      "z": 0,
      "name": "Soil_Dirt"
    },
    {
      "x": 1,
      "y": -2,
      "z": 0,
      "name": "Soil_Dirt"
    },
    {
      "x": 1,
      "y": -1,
      "z": 1,
      "name": "Soil_Dirt"
    },
    {
      "x": 1,
      "y": -2,
      "z": 1,
      "name": "Soil_Dirt"
    }
  ],
  "entities": [
    {
      "Components": {
        "Transform": {
          "Position": {
            "X": 0.5,
            "Y": 1.5,
            "Z": 0.5
          },
          "Rotation": {
            "Pitch": 0.0,
            "Yaw": 0.0,
            "Roll": 0.0
          }
        },
        "TriggerVolume": {
          "Shape": {
            "Type": "Box",
            "Min": {
              "X": -0.5,
              "Y": -0.5,
              "Z": -0.5
            },
            "Max": {
              "X": 0.5,
              "Y": 0.5,
              "Z": 0.5
            }
          },
          "Effects": [
            {
              "Type": "EntityEffect",
              "Event": "BLOCK_PLACED",
              "Interval": 0.0,
              "Delay": 0.0,
              "Effect": "Food_Health_Regen_Medium",
              "Mode": "Apply",
              "Duration": -1.0
            },
            {
              "Type": "PlaySound",
              "Event": "BLOCK_PLACED",
              "SoundEvent": "SFX_Shrine_Bless",
              "Volume": 1.0,
              "Pitch": 1.0
            },
            {
              "Type": "PlayVfx",
              "Event": "BLOCK_PLACED",
              "ParticleSystem": "Aura_Heal",
              "Offset": {
                "X": 0.0,
                "Y": 0.5,
                "Z": 0.0
              },
              "AtEntity": false,
              "Scale": 1.0,
              "Duration": 2.0
            },
            {
              "Type": "ReplaceBlockType",
              "Event": "BLOCK_PLACED",
              "Delay": 120.0,
              "FromBlockTypes": [
                "Plant_Fruit_Apple"
              ],
              "ToBlockType": "Empty"
            }
          ],
          "Conditions": [
            {
              "Type": "BlockTypeCondition",
              "Event": "BLOCK_PLACED",
              "BlockType": [
                "Plant_Fruit_Apple"
              ]
            }
          ],
          "Enabled": true,
          "TargetTypes": [
            "Player"
          ],
          "KeepLoaded": false,
          "PrefabIndex": 0
        }
      }
    },
    {
      "Components": {
        "Transform": {
          "Position": {
            "X": -0.5,
            "Y": 1.5,
            "Z": -0.5
          },
          "Rotation": {
            "Pitch": 0.0,
            "Yaw": 0.0,
            "Roll": 0.0
          }
        },
        "TriggerVolume": {
          "Shape": {
            "Type": "Box",
            "Min": {
              "X": -3.0,
              "Y": -2.0,
              "Z": -3.0
            },
            "Max": {
              "X": 3.0,
              "Y": 2.0,
              "Z": 3.0
            }
          },
          "Effects": [
            {
              "Type": "PlaceBlock",
              "Event": "ENTER",
              "BlockType": "Plant_Fruit_Apple",
              "Origin": "VolumeOrigin",
              "Position": {
                "X": 0.0,
                "Y": 0.0,
                "Z": 0.0
              },
              "ReplaceMode": "OnlyAir"
            },
            {
              "Type": "PlayVfx",
              "Event": "ENTER",
              "ParticleSystem": "Aura_Heal",
              "Offset": {
                "X": 0.0,
                "Y": 0.5,
                "Z": 0.0
              },
              "AtEntity": false,
              "Scale": 1.0,
              "Duration": 2.0
            }
          ],
          "Conditions": [
            {
              "Type": "CooldownCondition",
              "Event": "ENTER",
              "Cooldown": 600.0,
              "Scope": "WHOLE_VOLUME"
            }
          ],
          "Enabled": true,
          "TargetTypes": [
            "Player"
          ],
          "KeepLoaded": false,
          "PrefabIndex": 1
        }
      }
    }
  ]
}
